LOG INTO HUGGING FACE
The token has not been saved to the git credentials helper. Pass `add_to_git_credential=True` in this function directly or `--add-to-git-credential` if using via `huggingface-cli` if you want to set the git credential as well.
Token is valid (permission: read).
Your token has been saved to /home/dan/.cache/huggingface/token
Login successful
load model
`config.hidden_act` is ignored, you should use `config.hidden_activation` instead.
Gemma's activation function will be set to `gelu_pytorch_tanh`. Please, use
`config.hidden_activation` if you want to override this behaviour.
See https://github.com/huggingface/transformers/pull/29402 for more details.
Loading checkpoint shards: 100%|██████████| 2/2 [00:01<00:00,  1.46it/s]
tokenizer
load data
Data loaded
Traceback (most recent call last):
  File "/home/dan/miniconda3/envs/danEnv/lib/python3.11/site-packages/pandas/core/indexes/base.py", line 3805, in get_loc
    return self._engine.get_loc(casted_key)
           ^^^^^^^^^^^^^^^^^^^^^^^^^^^^^^^^
  File "index.pyx", line 167, in pandas._libs.index.IndexEngine.get_loc
  File "index.pyx", line 196, in pandas._libs.index.IndexEngine.get_loc
  File "pandas/_libs/hashtable_class_helper.pxi", line 7081, in pandas._libs.hashtable.PyObjectHashTable.get_item
  File "pandas/_libs/hashtable_class_helper.pxi", line 7089, in pandas._libs.hashtable.PyObjectHashTable.get_item
KeyError: 'no_context'
The above exception was the direct cause of the following exception:
Traceback (most recent call last):
  File "/home/dan/mini_temporal/training/fine_tune_gemma_halfway.py", line 261, in <module>
    main()
  File "/home/dan/mini_temporal/training/fine_tune_gemma_halfway.py", line 184, in main
    train_data = other_preprocessing(train, tokenizer, args.model_context)
                 ^^^^^^^^^^^^^^^^^^^^^^^^^^^^^^^^^^^^^^^^^^^^^^^^^^^^^^^^^
  File "/home/dan/mini_temporal/training/fine_tune_gemma_halfway.py", line 115, in other_preprocessing
    print(df['no_context'].iloc[0])
          ~~^^^^^^^^^^^^^^
  File "/home/dan/miniconda3/envs/danEnv/lib/python3.11/site-packages/pandas/core/frame.py", line 4090, in __getitem__
    indexer = self.columns.get_loc(key)
              ^^^^^^^^^^^^^^^^^^^^^^^^^
  File "/home/dan/miniconda3/envs/danEnv/lib/python3.11/site-packages/pandas/core/indexes/base.py", line 3812, in get_loc
    raise KeyError(key) from err
KeyError: 'no_context'